<?xml version="1.0"?>
<robot name="my_robot">

  <!-- ==================== -->
  <!--       BASE LINK      -->
  <!-- ==================== -->
  <link name="base_footprint"/>

  <joint name="base_joint" type="fixed">
    <parent link="base_footprint"/>
    <child link="base_link"/>
    <origin xyz="0 0 0.05" rpy="0 0 0"/>
  </joint>

  <link name="base_link">
    <visual>
      <geometry>
        <box size="0.3 0.2 0.1"/>
      </geometry>
      <material name="blue">
        <color rgba="0.2 0.4 0.8 1.0"/>
      </material>
    </visual>
    <collision>
      <geometry>
        <box size="0.3 0.2 0.1"/>
      </geometry>
    </collision>
    <inertial>
      <mass value="5.0"/>
      <inertia ixx="0.02" ixy="0" ixz="0"
               iyy="0.04" iyz="0" izz="0.05"/>
    </inertial>
  </link>

  <!-- ==================== -->
  <!--     LEFT WHEEL       -->
  <!-- ==================== -->
  <joint name="left_wheel_joint" type="continuous">
    <parent link="base_link"/>
    <child link="left_wheel"/>
    <origin xyz="-0.05 0.125 -0.01" rpy="-1.5708 0 0"/>
    <axis xyz="0 0 1"/>
  </joint>

  <link name="left_wheel">
    <visual>
      <geometry>
        <cylinder radius="0.04" length="0.03"/>
      </geometry>
      <material name="black">
        <color rgba="0.1 0.1 0.1 1.0"/>
      </material>
    </visual>
    <collision>
      <geometry>
        <cylinder radius="0.04" length="0.03"/>
      </geometry>
    </collision>
    <inertial>
      <mass value="0.5"/>
      <inertia ixx="0.0003" ixy="0" ixz="0"
               iyy="0.0003" iyz="0" izz="0.0004"/>
    </inertial>
  </link>

  <!-- ==================== -->
  <!--     RIGHT WHEEL      -->
  <!-- ==================== -->
  <joint name="right_wheel_joint" type="continuous">
    <parent link="base_link"/>
    <child link="right_wheel"/>
    <origin xyz="-0.05 -0.125 -0.01" rpy="1.5708 0 0"/>
    <axis xyz="0 0 -1"/>
  </joint>

  <link name="right_wheel">
    <visual>
      <geometry>
        <cylinder radius="0.04" length="0.03"/>
      </geometry>
      <material name="black">
        <color rgba="0.1 0.1 0.1 1.0"/>
      </material>
    </visual>
    <collision>
      <geometry>
        <cylinder radius="0.04" length="0.03"/>
      </geometry>
    </collision>
    <inertial>
      <mass value="0.5"/>
      <inertia ixx="0.0003" ixy="0" ixz="0"
               iyy="0.0003" iyz="0" izz="0.0004"/>
    </inertial>
  </link>

  <!-- ==================== -->
  <!--     CASTER WHEEL     -->
  <!-- ==================== -->
  <joint name="caster_joint" type="fixed">
    <parent link="base_link"/>
    <child link="caster_wheel"/>
    <origin xyz="0.1 0 -0.025" rpy="0 0 0"/>
  </joint>

  <link name="caster_wheel">
    <visual>
      <geometry>
        <sphere radius="0.025"/>
      </geometry>
      <material name="gray">
        <color rgba="0.5 0.5 0.5 1.0"/>
      </material>
    </visual>
    <collision>
      <geometry>
        <sphere radius="0.025"/>
      </geometry>
    </collision>
    <inertial>
      <mass value="0.2"/>
      <inertia ixx="0.0001" ixy="0" ixz="0"
               iyy="0.0001" iyz="0" izz="0.0001"/>
    </inertial>
  </link>

  <!-- ==================== -->
  <!--      LIDAR LINK      -->
  <!--   (from ros_03)      -->
  <!-- ==================== -->
  <joint name="lidar_joint" type="fixed">
    <parent link="base_link"/>
    <child link="lidar_link"/>
    <origin xyz="0.05 0 0.075" rpy="0 0 0"/>
  </joint>

  <link name="lidar_link">
    <visual>
      <geometry>
        <cylinder radius="0.03" length="0.04"/>
      </geometry>
      <material name="dark_gray">
        <color rgba="0.15 0.15 0.15 1.0"/>
      </material>
    </visual>
    <collision>
      <geometry>
        <cylinder radius="0.03" length="0.04"/>
      </geometry>
    </collision>
    <inertial>
      <mass value="0.1"/>
      <inertia ixx="0.0001" ixy="0" ixz="0"
               iyy="0.0001" iyz="0" izz="0.0001"/>
    </inertial>
  </link>

  <!-- ============================== -->
  <!--      CAMERA LINK (NEW)         -->
  <!-- ============================== -->
  <joint name="camera_joint" type="fixed">
    <parent link="base_link"/>
    <child link="camera_link"/>
    <!-- Mount the camera at the front of the robot, slightly above body -->
    <origin xyz="0.15 0 0.04" rpy="0 0 0"/>
  </joint>

  <link name="camera_link">
    <visual>
      <geometry>
        <box size="0.03 0.06 0.03"/>
      </geometry>
      <material name="camera_dark">
        <color rgba="0.05 0.05 0.05 1.0"/>
      </material>
    </visual>
    <collision>
      <geometry>
        <box size="0.03 0.06 0.03"/>
      </geometry>
    </collision>
    <inertial>
      <mass value="0.05"/>
      <inertia ixx="0.00005" ixy="0" ixz="0"
               iyy="0.00005" iyz="0" izz="0.00005"/>
    </inertial>
  </link>

  <!-- Optical frame: ROS convention (x-right, y-down, z-forward) -->
  <joint name="camera_optical_joint" type="fixed">
    <parent link="camera_link"/>
    <child link="camera_link_optical"/>
    <origin xyz="0 0 0" rpy="-1.5708 0 -1.5708"/>
  </joint>

  <link name="camera_link_optical"/>

  <!-- ==================== -->
  <!--    GAZEBO PLUGINS    -->
  <!-- ==================== -->

  <!-- Diff drive plugin -->
  <gazebo>
    <plugin filename="gz-sim-diff-drive-system"
            name="gz::sim::systems::DiffDrive">
      <left_joint>left_wheel_joint</left_joint>
      <right_joint>right_wheel_joint</right_joint>
      <wheel_separation>0.25</wheel_separation>
      <wheel_radius>0.04</wheel_radius>
      <topic>cmd_vel</topic>
      <odom_topic>odom</odom_topic>
      <frame_id>odom</frame_id>
      <child_frame_id>base_footprint</child_frame_id>
      <odom_publish_frequency>30</odom_publish_frequency>
    </plugin>
  </gazebo>

  <!-- Joint state publisher plugin -->
  <gazebo>
    <plugin filename="gz-sim-joint-state-publisher-system"
            name="gz::sim::systems::JointStatePublisher">
      <joint_name>left_wheel_joint</joint_name>
      <joint_name>right_wheel_joint</joint_name>
      <topic>joint_states</topic>
    </plugin>
  </gazebo>

  <!-- ============================================ -->
  <!--   GPU LIDAR SENSOR (from ros_03)             -->
  <!-- ============================================ -->
  <gazebo reference="lidar_link">
    <sensor name="lidar" type="gpu_lidar">
      <pose>0 0 0 0 0 0</pose>
      <topic>scan</topic>
      <gz_frame_id>lidar_link</gz_frame_id>
      <update_rate>10</update_rate>
      <always_on>true</always_on>
      <visualize>true</visualize>
      <ray>
        <scan>
          <horizontal>
            <samples>360</samples>
            <resolution>1</resolution>
            <min_angle>-3.14159</min_angle>
            <max_angle>3.14159</max_angle>
          </horizontal>
          <vertical>
            <samples>1</samples>
            <resolution>1</resolution>
            <min_angle>0</min_angle>
            <max_angle>0</max_angle>
          </vertical>
        </scan>
        <range>
          <min>0.10</min>
          <max>10.0</max>
          <resolution>0.01</resolution>
        </range>
        <noise>
          <type>gaussian</type>
          <mean>0.0</mean>
          <stddev>0.01</stddev>
        </noise>
      </ray>
    </sensor>
  </gazebo>

  <!-- ============================================ -->
  <!--   CAMERA SENSOR (NEW)                        -->
  <!-- ============================================ -->
  <gazebo reference="camera_link">
    <sensor name="camera" type="camera">
      <pose>0 0 0 0 0 0</pose>
      <topic>camera/image_raw</topic>
      <gz_frame_id>camera_link_optical</gz_frame_id>
      <update_rate>15</update_rate>
      <always_on>true</always_on>
      <visualize>true</visualize>
      <camera>
        <horizontal_fov>1.3962634</horizontal_fov>
        <image>
          <width>320</width>
          <height>240</height>
          <format>R8G8B8</format>
        </image>
        <clip>
          <near>0.05</near>
          <far>50.0</far>
        </clip>
        <noise>
          <type>gaussian</type>
          <mean>0.0</mean>
          <stddev>0.005</stddev>
        </noise>
      </camera>
    </sensor>
  </gazebo>

  <!-- Gazebo colors -->
  <gazebo reference="base_link">
    <material>
      <ambient>0.2 0.4 0.8 1.0</ambient>
      <diffuse>0.2 0.4 0.8 1.0</diffuse>
    </material>
  </gazebo>

  <gazebo reference="left_wheel">
    <material>
      <ambient>0.1 0.1 0.1 1.0</ambient>
      <diffuse>0.1 0.1 0.1 1.0</diffuse>
    </material>
    <mu1>1.0</mu1>
    <mu2>1.0</mu2>
  </gazebo>

  <gazebo reference="right_wheel">
    <material>
      <ambient>0.1 0.1 0.1 1.0</ambient>
      <diffuse>0.1 0.1 0.1 1.0</diffuse>
    </material>
    <mu1>1.0</mu1>
    <mu2>1.0</mu2>
  </gazebo>

  <gazebo reference="caster_wheel">
    <material>
      <ambient>0.5 0.5 0.5 1.0</ambient>
      <diffuse>0.5 0.5 0.5 1.0</diffuse>
    </material>
    <mu1>0.0</mu1>
    <mu2>0.0</mu2>
  </gazebo>

  <gazebo reference="lidar_link">
    <material>
      <ambient>0.15 0.15 0.15 1.0</ambient>
      <diffuse>0.15 0.15 0.15 1.0</diffuse>
    </material>
  </gazebo>

  <gazebo reference="camera_link">
    <material>
      <ambient>0.05 0.05 0.05 1.0</ambient>
      <diffuse>0.05 0.05 0.05 1.0</diffuse>
    </material>
  </gazebo>

</robot>
